[2024-05-23 06:18:15,690] __main__:86 INFO :: Using SDK version (local emulation): 1.10.3
[2024-05-23 06:18:15,690] qmenta.sdk.client:36 INFO :: Launching: tool:run
[2024-05-23 06:18:15,690] qmenta.sdk.local.client:20 INFO :: State = 'running' for local execution
[2024-05-23 06:18:15,692] qmenta.sdk.client:54 ERROR :: No module named 'matplotlib'
Traceback (most recent call last):
  File "/usr/local/lib/python3.8/dist-packages/qmenta/sdk/client.py", line 42, in __call__
    class_or_func = load_user_analysis(user_script_path)
  File "/usr/local/lib/python3.8/dist-packages/qmenta/sdk/client.py", line 101, in load_user_analysis
    user_module = importlib.import_module(module_name)
  File "/usr/lib/python3.8/importlib/__init__.py", line 127, in import_module
    return _bootstrap._gcd_import(name[level:], package, level)
  File "<frozen importlib._bootstrap>", line 1014, in _gcd_import
  File "<frozen importlib._bootstrap>", line 991, in _find_and_load
  File "<frozen importlib._bootstrap>", line 975, in _find_and_load_unlocked
  File "<frozen importlib._bootstrap>", line 671, in _load_unlocked
  File "<frozen importlib._bootstrap_external>", line 848, in exec_module
  File "<frozen importlib._bootstrap>", line 219, in _call_with_frames_removed
  File "/qmenta/tool.py", line 2, in <module>
    import matplotlib
ModuleNotFoundError: No module named 'matplotlib'
[2024-05-23 06:18:15,692] qmenta.sdk.local.context:147 INFO :: Progress: None -> Error
[2024-05-23 06:18:15,692] qmenta.sdk.local.client:20 INFO :: State = 'exception' for local execution
